#VRML_SIM R2025a utf8

EXTERNPROTO "https://raw.githubusercontent.com/cyberbotics/webots/R2025a/projects/objects/backgrounds/protos/TexturedBackground.proto"
EXTERNPROTO "https://raw.githubusercontent.com/cyberbotics/webots/R2025a/projects/objects/backgrounds/protos/TexturedBackgroundLight.proto"
EXTERNPROTO "https://raw.githubusercontent.com/cyberbotics/webots/R2025a/projects/objects/floors/protos/RectangleArena.proto"
EXTERNPROTO "https://raw.githubusercontent.com/cyberbotics/webots/R2025a/projects/appearances/protos/MattePaint.proto"
EXTERNPROTO "https://raw.githubusercontent.com/cyberbotics/webots/R2025a/projects/appearances/protos/TireRubber.proto"

WorldInfo {
  info [
    "Description: Examples of four wheels vehicles"
  ]
  title "Four Wheels"
  basicTimeStep 8
  FPS 120
  lineScale 0.2
}
Viewpoint {
  orientation 0.09075647598369513 -0.5837792794711022 -0.8068240297160353 5.878618643053207
  position -3.3029845999510155 -1.2397903154009347 1.0534896812410834
  follow "Alamak"
  followType "Mounted Shot"
}
TexturedBackground {
}
TexturedBackgroundLight {
}
RectangleArena {
  floorSize 50 50
  floorTileSize 2 2
}
DEF ALAMAK Robot {
  translation 0 0 0.032
  children [
    DEF ALAMAK_BODY_SH Shape {
      appearance MattePaint {
        baseColor 0.168627 0.168627 0.168627
      }
      geometry Box {
        size 0.265 0.125 0.025
      }
    }
    DEF ALAMAK_RL_WHEEL HingeJoint {
      jointParameters HingeJointParameters {
        axis 0 1 0
        anchor -0.12 0.08 0
      }
      device [
        PositionSensor {
          name "rl_encoder"
          resolution 0.00153398
        }
        RotationalMotor {
          name "rl_motor"
          maxVelocity 100
        }
      ]
      endPoint Solid {
        translation -0.12000064696667458 0.08000075424238581 -5.762730195466481e-09
        rotation -0.7707191538696051 0.00015734366194802455 -0.6371749846796343 6.2828110755565625
        children [
          DEF ALAMAK_WHEEL_POSE Pose {
            rotation 1 0 0 -1.5707953071795862
            children [
              DEF ALAMAK_WHEEL_SH Shape {
                appearance TireRubber {
                }
                geometry DEF ALAMAK_WHEEL_CYL Cylinder {
                  height 0.026
                  radius 0.032
                }
              }
            ]
          }
        ]
        name "alamak_rl_wheel"
        boundingObject USE ALAMAK_WHEEL_POSE
        physics Physics {
        }
      }
    }
    DEF ALAMAK_RR_WHEEL HingeJoint {
      jointParameters HingeJointParameters {
        axis 0 1 0
        anchor -0.12 -0.08 0
      }
      device [
        RotationalMotor {
          name "rr_motor"
          maxVelocity 100
        }
        PositionSensor {
          name "rr_encoder"
          resolution 0.00153398
        }
      ]
      endPoint Solid {
        translation -0.12000144537206893 -0.08000159518239915 -1.4540245600655905e-06
        rotation -0.770721298305927 0.00015733431760616245 -0.6371723907888186 6.282811097415651
        children [
          USE ALAMAK_WHEEL_POSE
        ]
        name "alamak_rr_wheel"
        boundingObject USE ALAMAK_WHEEL_POSE
        physics Physics {
        }
      }
    }
    DEF ALAMAK_FL_WHEEL Hinge2Joint {
      jointParameters HingeJointParameters {
        axis 0 0 1
        anchor 0.065 0.08 0
      }
      jointParameters2 JointParameters {
        axis 0 1 0
      }
      device [
        RotationalMotor {
          name "fl_servo"
          maxTorque 12
        }
        PositionSensor {
          name "fl_servo_encoder"
        }
      ]
      endPoint Solid {
        translation 0.06500092337164304 0.08000155513982896 9.557792592895883e-07
        children [
          USE ALAMAK_WHEEL_POSE
        ]
        name "alamak_fl_wheel"
        boundingObject USE ALAMAK_WHEEL_POSE
        physics Physics {
        }
      }
    }
    DEF ALAMAK_FR_WHEEL Hinge2Joint {
      jointParameters HingeJointParameters {
        axis 0 0 1
        anchor 0.065 -0.08 0
      }
      jointParameters2 JointParameters {
        axis 0 1 0
      }
      device [
        RotationalMotor {
          name "fr_servo"
          maxTorque 12
        }
        PositionSensor {
          name "fr_servo_encoder"
        }
      ]
      endPoint Solid {
        translation 0.06499964028409694 -0.0800008969279732 1.1203611734243677e-06
        children [
          USE ALAMAK_WHEEL_POSE
        ]
        name "alamak_fr_wheel"
        boundingObject USE ALAMAK_WHEEL_POSE
        physics Physics {
        }
      }
    }
    InertialUnit {
      name "imu_gyro"
    }
    Accelerometer {
      name "imu_accel"
    }
    Compass {
      name "imu_compass"
    }
    Camera {
      translation 0.06 0 0.125
      children [
        Solid {
          children [
            Pose {
              rotation 1 0 0 -1.5708
              children [
                DEF BOARD Group {
                  children [
                    Shape {
                      appearance PBRAppearance {
                        baseColorMap ImageTexture {
                          url [
                            "https://raw.githubusercontent.com/cyberbotics/webots/R2025a/projects/robots/nvidia/jetbot/protos/textures/raspberry_pi_camera.jpg"
                          ]
                        }
                        roughness 1
                        metalness 0
                      }
                      geometry IndexedFaceSet {
                        coord Coordinate {
                          point [
                            -0.0005 -0.01199995592153876 -0.011999999999919044
                            -0.0005 0.01200004407846124 -0.011999999999919044
                            -0.0005 -0.01200004407846124 0.011999999999919044
                            -0.0005 0.01199995592153876 0.011999999999919044
                            0.0005 -0.01199995592153876 -0.011999999999919044
                            0.0005 0.01200004407846124 -0.011999999999919044
                            0.0005 -0.01200004407846124 0.011999999999919044
                            0.0005 0.01199995592153876 0.011999999999919044
                          ]
                        }
                        texCoord TextureCoordinate {
                          point [
                            0 0
                            1 0
                            0 1
                            1 1
                            0.0001 0.0001
                            0.9999 0.0001
                            0.0001 0.9999
                            0.9999 0.9999
                          ]
                        }
                        coordIndex [
                          1, 0, 2, 3, -1, 4, 5, 7, 6, -1, 5, 1, 3, 7, -1, 0, 4, 6, 2, -1, 7, 3, 2, 6, -1, 4, 0, 1, 5, -1
                        ]
                        texCoordIndex [
                          1, 0, 2, 3, -1, 0, 1, 3, 2, -1, 1, 5, 7, 3, -1, 0, 4, 6, 2, -1, 7, 3, 2, 6, -1, 0, 4, 5, 1, -1
                        ]
                      }
                    }
                  ]
                }
              ]
            }
            Pose {
              translation -0.003 0 -0.0015
              children [
                Shape {
                  appearance DEF LIGHT_GRAY_APPEARANCE PBRAppearance {
                    baseColor 0.729412 0.741176 0.713725
                    roughness 0.5
                    metalness 0.2
                  }
                  geometry Box {
                    size 0.004 0.022 0.027
                  }
                }
              ]
            }
          ]
        }
      ]
      name "rpi_camera_v2"
      fieldOfView 1.0472
      width 820
      height 616
    }
  ]
  name "Alamak"
  description "NXP Cup Alamak - model vehicle"
  boundingObject USE ALAMAK_BODY_SH
  physics Physics {
    density -1
    mass 4
    centerOfMass [
      -0.03 0 0.05
    ]
  }
  controller "alamak"
  supervisor TRUE
}
